Workbook

Sheet Executive Dashboard
A1: E-Commerce Sales Performance Dashboard
A2: 2025 | Sales, Profitability & Market Performance
A4: Revenue | D4: Gross Profit | G4: Profit Margin | J4: Total Orders
A5: =KPI_Summary!B2 -> 147019.1 | D5: =KPI_Summary!B4 -> 58998.1 | G5: =KPI_Summary!B5 -> 0.40129548 | J5: =KPI_Summary!B6 -> 550
A8: Average Order Value | D8: Top Revenue Market
A9: =KPI_Summary!B7 -> 267.30745 | D9: =INDEX(Pivot_Country!A4:A11,MATCH(MAX(Pivot_Country!B4:B11),Pivot_Country!B4:B11,0)) -> United Arab Emirates
A12: Performance Overview
A50: Key Business Insights
A52: Insight 1 — Top market
A53: UAE is the highest-revenue market at $24.44K.
A55: Insight 2 — Product concentration
A56: 🖥️ The two monitor products generate $61.35K, approximately 41.7% of total revenue.
A58: Insight 3 — Margin opportunity
A59: 💰 Accessories have the highest gross margin at 50.23%, while Electronics has the lowest at 37.55%.
A61: Insight 4 — Monthly performance
A62: 📈 November was the strongest month with $17.11K in revenue, while February was the weakest at $6.60K.

Sheet Project_Brief
A1: PROJECT 1 | B1: International E-commerce Sales Data Cleaning & Executive Dashboard | C1: Status
A2: OBJECTIVE | B2: Clean a messy sales dataset, calculate business KPIs, and create an executive dashboard in Excel. | C2: Done
A3: TASK 1 | B3: Identify and remove duplicate records. | C3: Done
A4: TASK 2 | B4: Standardize Country, Customer_Name, Payment_Method and Order_Status. | C4: Done
A5: TASK 3 | B5: Handle missing values appropriately and document your approach. | C5: Done
A6: TASK 4 | B6: Validate email addresses and flag invalid records. | C6: Done
A7: TASK 5 | B7: Create Total Sales = Quantity × Unit Price × (1 − Discount). | C7: Done
A8: TASK 6 | B8: Create Total Cost = Quantity × Unit Cost. | C8: Done
A9: TASK 7 | B9: Create Gross Profit = Total Sales − Total Cost. | C9: Done
A10: TASK 8 | B10: Create Profit Margin % = Gross Profit ÷ Total Sales. | C10: Done
A11: TASK 9 | B11: Analyse Sales, Profit, Orders and Average Order Value by month and country. | C11: Done
A12: TASK 10 | B12: Identify top 5 products and best-performing countries. | C12: Done
... A14: TASK 12 | B14: Write 5 business insights and 3 recommendations based on your analysis. | C14: Done
A18: Task | B18: Status
A19: Data Cleaning | B19: Done
A20: Data Validation | B20: Done
A21: KPI Analysis | B21: Done
A22: Category Analysis | B22: Done
A23: Country Analysis | B23: Done
A24: Time Analysis | B24: Done
A25: Product Analysis | B25: Done
A26: Dashboard | B26: Done
A27: Documentation | B27: Done
A29: Percentage | B29: =COUNTIF(B19:B27,"Done")/COUNTA(B19:B27) -> 1

Sheet Pivot_Product
A3: Row Labels | B3: Sum of Revenue_USD | C3: Sum of Gross_Profit_USD | D3: Gross Margin
A4: Monitor 27-inch | B4: 33920.25 | C4: 11420.25 | D4: =C4/B4 -> 0.33667942
A5: Monitor 24-inch | B5: 27431.25 | C5: 10001.25 | D5: =C5/B5 -> 0.3645933
A6: Office Chair | B6: 17598 | C6: 6473 | D6: =C6/B6 -> 0.36782589
A7: Headphones | B7: 13986.75 | C7: 6242.75 | D7: =C7/B7 -> 0.44633314
A8: SSD 1TB | B8: 10014.2 | C8: 3972.2 | D8: =C8/B8 -> 0.39665675
A9: Webcam | B9: 8496 | C9: 3816 | D9: =C9/B9 -> 0.44915254
A10: Mechanical Keyboard | B10: 8414.25 | C10: 4136.25 | D10: =C10/B10 -> 0.49157679
A11: External HDD 2TB | B11: 7538.7 | C11: 2858.7 | D11: =C11/B11 -> 0.37920331
A12: USB-C Hub | B12: 6885.9 | C12: 3231.9 | D12: =C12/B12 -> 0.46935041
A13: Desk Lamp | B13: 5283 | C13: 2787 | D13: =C13/B13 -> 0.52754117
A14: Laptop Stand | B14: 5209.8 | C14: 2727.8 | D14: =C14/B14 -> 0.52359016
A15: Wireless Mouse | B15: 2241 | C15: 1331 | D15: =C15/B15 -> 0.59393128
A16: Grand Total | B16: 147019.1 | C16: 58998.1 | D16: =C16/B16 -> 0.40129548

Sheet Pivot_Country
A3: Row Labels | B3: Sum of Revenue_USD
A4: Australia | B4: 19511.05
A5: Canada | B5: 14616
A6: Germany | B6: 15601.1
A7: India | B7: 17289
A8: Singapore | B8: 21326.35
A9: United Arab Emirates | B9: 24443.25
A10: United Kingdom | B10: 15647.9
A11: United States | B11: 17255.75
A12: Unknown | B12: 1328.7
A13: Grand Total | B13: 147019.1

Sheet Pivot _Category
A3: Row Labels | B3: Sum of Revenue_USD | C3: Sum of Gross_Profit_USD
A4: Accessories | B4: 22750.95 | C4: 11426.95
A5: Electronics | B5: 83834.25 | C5: 31480.25
A6: Furniture | B6: 22881 | C6: 9260
A7: Storage | B7: 17552.9 | C7: 6830.9
A8: Grand Total | B8: 147019.1 | C8: 58998.1
A12: Row Labels | B12: Sum of Gross Margin
A13: Accessories | B13: 0.50226254
A14: Electronics | B14: 0.37550583
A15: Furniture | B15: 0.40470259
A16: Storage | B16: 0.38916077
A17: Grand Total | B17: 0.40129548

Sheet Pivot_Monthly
A3: Row Labels | B3: Sum of Revenue_USD | C3: Sum of Gross_Profit_USD
A4: 2025 | B4: 147019.1 | C4: 58998.1
A5: Jan | B5: 8896.65 | C5: 3504.65
A6: Feb | B6: 6599.5 | C6: 2987.5
A7: Mar | B7: 12881.55 | C7: 5040.55
A8: Apr | B8: 16177.35 | C8: 6337.35
A9: May | B9: 12989.75 | C9: 5413.75
A10: Jun | B10: 12847.4 | C10: 5248.4
A11: Jul | B11: 11353.95 | C11: 4496.95
A12: Aug | B12: 14305.05 | C12: 5677.05
A13: Sep | B13: 10804.6 | C13: 4532.6
A14: Oct | B14: 12654.5 | C14: 4841.5
A15: Nov | B15: 17111.2 | C15: 6660.2
... A17: Grand Total | B17: 147019.1 | C17: 58998.1

Sheet Clean_Data
A1: Order_ID | B1: Order_Date | C1: Customer_Name | D1: Customer_Name_Clean | E1: Country | F1: Country_clean | G1: Product | H1: Category | I1: Quantity | J1: Unit_Price_USD | K1: Unit_Cost_USD | L1: Discount | M1: Payment_Method | N1: Payment_Method_clean | O1: Order_Status | P1: Order_Status_Clean | Q1: Email_Validation | R1: Customer_Email | S1: Revenue_USD | T1: Cost_USD | U1: Gross_Profit_USD | V1: Profit_Margin
A2: ORD-10087 | B2: 45735 | C2: Liam Miller | D2: =PROPER(TRIM(C2)) -> Liam Miller | E2: UAE | F2: =IF(OR(UPPER(TRIM(E2))="AUS",UPPER(TRIM(E2))="AUSTRALIA"),"Australia",IF(OR(UPPER(TRIM(E2))="CAN",UPPER(TRIM(E2))="CANADA"),"Canada",IF(OR(UPPER(TRIM(E2))="DE",UPPER(TRIM(E2))="GERMANY"),"Germany",IF(OR(UPPER(TRIM(E2))="IN",UPPER(TRIM(E2))="INDIA"),"India",IF(OR(UPPER(TRIM(E2))="US",UPPER(TRIM(E2))="USA",UPPER(TRIM(E2))="UNITED STATES"),"United States",IF(OR(UPPER(TRIM(E2))="UK",UPPER(TRIM(E2))="U.K.",UPPER(TRIM(E2))="UNITED KINGDOM"),"United Kingdom",IF(OR(UPPER(TRIM(E2))="UAE",UPPER(TRIM(E2))="U.A.E.",UPPER(TRIM(E2))="UNITED ARAB EMIRATES"),"United Arab Emirates",IF(OR(UPPER(TRIM(E2))="SG",UPPER(TRIM(E2))="SINGAPORE"),"Singapore",TRIM(E2))))))))) -> United Arab Emirates | G2: Desk Lamp | H2: Furniture | I2: 3 | J2: 36 | K2: 16 | L2: 0 | M2: paypal | N2: PayPal | O2: Completed | P2: =PROPER(TRIM(O2)) -> Completed | Q2: =IF(TRIM(R2)="","Missing",IF(AND(ISNUMBER(SEARCH("@",R2)),ISNUMBER(SEARCH(".",R2,SEARCH("@",R2)+2))),"Valid","Invalid")) -> Valid | R2: liam.miller@example.com | S2: =I2*J2*(1-L2) -> 108 | T2: =I2*K2 -> 48 | U2: =S2-T2 -> 60 | V2: =IF(S2=0,0,U2/S2) -> 0.55555556
A3: ORD-10007 | B3: 45894 | C3: Ava Thomas | D3: =PROPER(TRIM(C3)) -> Ava Thomas | E3: UAE | F3: =IF(OR(UPPER(TRIM(E3))="AUS",UPPER(TRIM(E3))="AUSTRALIA"),"Australia",IF(OR(UPPER(TRIM(E3))="CAN",UPPER(TRIM(E3))="CANADA"),"Canada",IF(OR(UPPER(TRIM(E3))="DE",UPPER(TRIM(E3))="GERMANY"),"Germany",IF(OR(UPPER(TRIM(E3))="IN",UPPER(TRIM(E3))="INDIA"),"India",IF(OR(UPPER(TRIM(E3))="US",UPPER(TRIM(E3))="USA",UPPER(TRIM(E3))="UNITED STATES"),"United States",IF(OR(UPPER(TRIM(E3))="UK",UPPER(TRIM(E3))="U.K.",UPPER(TRIM(E3))="UNITED KINGDOM"),"United Kingdom",IF(OR(UPPER(TRIM(E3))="UAE",UPPER(TRIM(E3))="U.A.E.",UPPER(TRIM(E3))="UNITED ARAB EMIRATES"),"United Arab Emirates",IF(OR(UPPER(TRIM(E3))="SG",UPPER(TRIM(E3))="SINGAPORE"),"Singapore",TRIM(E3))))))))) -> United Arab Emirates | G3: Laptop Stand | H3: Accessories | I3: 4 | J3: 38 | K3: 17 | L3: 0 | M3: credit card | N3: =PROPER(TRIM(M3)) -> Credit Card | O3: Completed | P3: =PROPER(TRIM(O3)) -> Completed | Q3: =IF(TRIM(R3)="","Missing",IF(AND(ISNUMBER(SEARCH("@",R3)),ISNUMBER(SEARCH(".",R3,SEARCH("@",R3)+2))),"Valid","Invalid")) -> Valid | R3: ava.thomas@example.com | S3: =I3*J3*(1-L3) -> 152 | T3: =I3*K3 -> 68 | U3: =S3-T3 -> 84 | V3: =IF(S3=0,0,U3/S3) -> 0.55263158
A4: ORD-10143 | B4: 45777 | C4: alex morgan | D4: =PROPER(TRIM(C4)) -> Alex Morgan | E4: australia | F4: =IF(OR(UPPER(TRIM(E4))="AUS",UPPER(TRIM(E4))="AUSTRALIA"),"Australia",IF(OR(UPPER(TRIM(E4))="CAN",UPPER(TRIM(E4))="CANADA"),"Canada",IF(OR(UPPER(TRIM(E4))="DE",UPPER(TRIM(E4))="GERMANY"),"Germany",IF(OR(UPPER(TRIM(E4))="IN",UPPER(TRIM(E4))="INDIA"),"India",IF(OR(UPPER(TRIM(E4))="US",UPPER(TRIM(E4))="USA",UPPER(TRIM(E4))="UNITED STATES"),"United States",IF(OR(UPPER(TRIM(E4))="UK",UPPER(TRIM(E4))="U.K.",UPPER(TRIM(E4))="UNITED KINGDOM"),"United Kingdom",IF(OR(UPPER(TRIM(E4))="UAE",UPPER(TRIM(E4))="U.A.E.",UPPER(TRIM(E4))="UNITED ARAB EMIRATES"),"United Arab Emirates",IF(OR(UPPER(TRIM(E4))="SG",UPPER(TRIM(E4))="SINGAPORE"),"Singapore",TRIM(E4))))))))) -> Australia | G4: Wireless Mouse | H4: Accessories | I4: 1 | J4: 18 | K4: 7 | L4: 0.05 | M4: PayPal | N4: PayPal | O4: Completed | P4: =PROPER(TRIM(O4)) -> Completed | Q4: =IF(TRIM(R4)="","Missing",IF(AND(ISNUMBER(SEARCH("@",R4)),ISNUMBER(SEARCH(".",R4,SEARCH("@",R4)+2))),"Valid","Invalid")) -> Valid | R4: alex.morgan@example.com | S4: =I4*J4*(1-L4) -> 17.1 | T4: =I4*K4 -> 7 | U4: =S4-T4 -> 10.1 | V4: =IF(S4=0,0,U4/S4) -> 0.59064327
A5: ORD-10127 | B5: 45834 | C5: Liam Miller | D5: =PROPER(TRIM(C5)) -> Liam Miller | E5: UK | F5: =IF(OR(UPPER(TRIM(E5))="AUS",UPPER(TRIM(E5))="AUSTRALIA"),"Australia",IF(OR(UPPER(TRIM(E5))="CAN",UPPER(TRIM(E5))="CANADA"),"Canada",IF(OR(UPPER(TRIM(E5))="DE",UPPER(TRIM(E5))="GERMANY"),"Germany",IF(OR(UPPER(TRIM(E5))="IN",UPPER(TRIM(E5))="INDIA"),"India",IF(OR(UPPER(TRIM(E5))="US",UPPER(TRIM(E5))="USA",UPPER(TRIM(E5))="UNITED STATES"),"United States",IF(OR(UPPER(TRIM(E5))="UK",UPPER(TRIM(E5))="U.K.",UPPER(TRIM(E5))="UNITED KINGDOM"),"United Kingdom",IF(OR(UPPER(TRIM(E5))="UAE",UPPER(TRIM(E5))="U.A.E.",UPPER(TRIM(E5))="UNITED ARAB EMIRATES"),"United Arab Emirates",IF(OR(UPPER(TRIM(E5))="SG",UPPER(TRIM(E5))="SINGAPORE"),"Singapore",TRIM(E5))))))))) -> United Kingdom | G5: SSD 1TB | H5: Storage | I5: 1 | J5: 92 | K5: 53 | L5: 0 | M5: credit card | N5: =PROPER(TRIM(M5)) -> Credit Card | O5: Completed | P5: =PROPER(TRIM(O5)) -> Completed | Q5: =IF(TRIM(R5)="","Missing",IF(AND(ISNUMBER(SEARCH("@",R5)),ISNUMBER(SEARCH(".",R5,SEARCH("@",R5)+2))),"Valid","Invalid")) -> Valid | R5: liam.miller@example.com | S5: =I5*J5*(1-L5) -> 92 | T5: =I5*K5 -> 53 | U5: =S5-T5 -> 39 | V5: =IF(S5=0,0,U5/S5) -> 0.42391304
A6: ORD-10470 | B6: 46000 | C6: Lily Hall | D6: =PROPER(TRIM(C6)) -> Lily Hall | E6: AUS | F6: =IF(OR(UPPER(TRIM(E6))="AUS",UPPER(TRIM(E6))="AUSTRALIA"),"Australia",IF(OR(UPPER(TRIM(E6))="CAN",UPPER(TRIM(E6))="CANADA"),"Canada",IF(OR(UPPER(TRIM(E6))="DE",UPPER(TRIM(E6))="GERMANY"),"Germany",IF(OR(UPPER(TRIM(E6))="IN",UPPER(TRIM(E6))="INDIA"),"India",IF(OR(UPPER(TRIM(E6))="US",UPPER(TRIM(E6))="USA",UPPER(TRIM(E6))="UNITED STATES"),"United States",IF(OR(UPPER(TRIM(E6))="UK",UPPER(TRIM(E6))="U.K.",UPPER(TRIM(E6))="UNITED KINGDOM"),"United Kingdom",IF(OR(UPPER(TRIM(E6))="UAE",UPPER(TRIM(E6))="U.A.E.",UPPER(TRIM(E6))="UNITED ARAB EMIRATES"),"United Arab Emirates",IF(OR(UPPER(TRIM(E6))="SG",UPPER(TRIM(E6))="SINGAPORE"),"Singapore",TRIM(E6))))))))) -> Australia | G6: SSD 1TB | H6: Storage | I6: 1 | J6: 92 | K6: 53 | L6: 0.05 | M6: Bank Transfer | N6: =PROPER(TRIM(M6)) -> Bank Transfer | O6: Pending | P6: =PROPER(TRIM(O6)) -> Pending | Q6: =IF(TRIM(R6)="","Missing",IF(AND(ISNUMBER(SEARCH("@",R6)),ISNUMBER(SEARCH(".",R6,SEARCH("@",R6)+2))),"Valid","Invalid")) -> Valid | R6: lily.hall@example.com | S6: =I6*J6*(1-L6) -> 87.4 | T6: =I6*K6 -> 53 | U6: =S6-T6 -> 34.4 | V6: =IF(S6=0,0,U6/S6) -> 0.39359268
A7: ORD-10279 | B7: 45764 | C7: Sophia Taylor | D7: =PROPER(TRIM(C7)) -> Sophia Taylor | E7: germany | F7: =IF(OR(UPPER(TRIM(E7))="AUS",UPPER(TRIM(E7))="AUSTRALIA"),"Australia",IF(OR(UPPER(TRIM(E7))="CAN",UPPER(TRIM(E7))="CANADA"),"Canada",IF(OR(UPPER(TRIM(E7))="DE",UPPER(TRIM(E7))="GERMANY"),"Germany",IF(OR(UPPER(TRIM(E7))="IN",UPPER(TRIM(E7))="INDIA"),"India",IF(OR(UPPER(TRIM(E7))="US",UPPER(TRIM(E7))="USA",UPPER(TRIM(E7))="UNITED STATES"),"United States",IF(OR(UPPER(TRIM(E7))="UK",UPPER(TRIM(E7))="U.K.",UPPER(TRIM(E7))="UNITED KINGDOM"),"United Kingdom",IF(OR(UPPER(TRIM(E7))="UAE",UPPER(TRIM(E7))="U.A.E.",UPPER(TRIM(E7))="UNITED ARAB EMIRATES"),"United Arab Emirates",IF(OR(UPPER(TRIM(E7))="SG",UPPER(TRIM(E7))="SINGAPORE"),"Singapore",TRIM(E7))))))))) -> Germany | G7: External HDD 2TB | H7: Storage | I7: 5 | J7: 78 | K7: 45 | L7: 0.1 | M7: Debit Card | N7: =PROPER(TRIM(M7)) -> Debit Card | O7: Completed | P7: =PROPER(TRIM(O7)) -> Completed | Q7: =IF(TRIM(R7)="","Missing",IF(AND(ISNUMBER(SEARCH("@",R7)),ISNUMBER(SEARCH(".",R7,SEARCH("@",R7)+2))),"Valid","Invalid")) -> Valid | R7: sophia.taylor@example.com | S7: =I7*J7*(1-L7) -> 351 | T7: =I7*K7 -> 225 | U7: =S7-T7 -> 126 | V7: =IF(S7=0,0,U7/S7) -> 0.35897436
A8: ORD-10463 | B8: 45900 | C8: Daniel Harris | D8: =PROPER(TRIM(C8)) -> Daniel Harris | E8: USA | F8: =IF(OR(UPPER(TRIM(E8))="AUS",UPPER(TRIM(E8))="AUSTRALIA"),"Australia",IF(OR(UPPER(TRIM(E8))="CAN",UPPER(TRIM(E8))="CANADA"),"Canada",IF(OR(UPPER(TRIM(E8))="DE",UPPER(TRIM(E8))="GERMANY"),"Germany",IF(OR(UPPER(TRIM(E8))="IN",UPPER(TRIM(E8))="INDIA"),"India",IF(OR(UPPER(TRIM(E8))="US",UPPER(TRIM(E8))="USA",UPPER(TRIM(E8))="UNITED STATES"),"United States",IF(OR(UPPER(TRIM(E8))="UK",UPPER(TRIM(E8))="U.K.",UPPER(TRIM(E8))="UNITED KINGDOM"),"United Kingdom",IF(OR(UPPER(TRIM(E8))="UAE",UPPER(TRIM(E8))="U.A.E.",UPPER(TRIM(E8))="UNITED ARAB EMIRATES"),"United Arab Emirates",IF(OR(UPPER(TRIM(E8))="SG",UPPER(TRIM(E8))="SINGAPORE"),"Singapore",TRIM(E8))))))))) -> United States | G8: Desk Lamp | H8: Furniture | I8: 2 | J8: 36 | K8: 16 | L8: 0.15 | M8: Bank Transfer | N8: =PROPER(TRIM(M8)) -> Bank Transfer | O8: Completed | P8: =PROPER(TRIM(O8)) -> Completed | Q8: =IF(TRIM(R8)="","Missing",IF(AND(ISNUMBER(SEARCH("@",R8)),ISNUMBER(SEARCH(".",R8,SEARCH("@",R8)+2))),"Valid","Invalid")) -> Invalid | R8: daniel.harris@example | S8: =I8*J8*(1-L8) -> 61.2 | T8: =I8*K8 -> 32 | U8: =S8-T8 -> 29.2 | V8: =IF(S8=0,0,U8/S8) -> 0.47712418
A9: ORD-10041 | B9: 45753 | C9: Mia White | D9: =PROPER(TRIM(C9)) -> Mia White | E9: germany | F9: =IF(OR(UPPER(TRIM(E9))="AUS",UPPER(TRIM(E9))="AUSTRALIA"),"Australia",IF(OR(UPPER(TRIM(E9))="CAN",UPPER(TRIM(E9))="CANADA"),"Canada",IF(OR(UPPER(TRIM(E9))="DE",UPPER(TRIM(E9))="GERMANY"),"Germany",IF(OR(UPPER(TRIM(E9))="IN",UPPER(TRIM(E9))="INDIA"),"India",IF(OR(UPPER(TRIM(E9))="US",UPPER(TRIM(E9))="USA",UPPER(TRIM(E9))="UNITED STATES"),"United States",IF(OR(UPPER(TRIM(E9))="UK",UPPER(TRIM(E9))="U.K.",UPPER(TRIM(E9))="UNITED KINGDOM"),"United Kingdom",IF(OR(UPPER(TRIM(E9))="UAE",UPPER(TRIM(E9))="U.A.E.",UPPER(TRIM(E9))="UNITED ARAB EMIRATES"),"United Arab Emirates",IF(OR(UPPER(TRIM(E9))="SG",UPPER(TRIM(E9))="SINGAPORE"),"Singapore",TRIM(E9))))))))) -> Germany | G9: Headphones | H9: Electronics | I9: 4 | J9: 85 | K9: 44 | L9: 0 | M9: credit card | N9: =PROPER(TRIM(M9)) -> Credit Card | O9: Completed | P9: =PROPER(TRIM(O9)) -> Completed | Q9: =IF(TRIM(R9)="","Missing",IF(AND(ISNUMBER(SEARCH("@",R9)),ISNUMBER(SEARCH(".",R9,SEARCH("@",R9)+2))),"Valid","Invalid")) -> Valid | R9: mia.white@example.com | S9: =I9*J9*(1-L9) -> 340 | T9: =I9*K9 -> 176 | U9: =S9-T9 -> 164 | V9: =IF(S9=0,0,U9/S9) -> 0.48235294
A10: ORD-10207 | B10: 45743 | C10: Grace Moore | D10: =PROPER(TRIM(C10)) -> Grace Moore | E10: SG | F10: =IF(OR(UPPER(TRIM(E10))="AUS",UPPER(TRIM(E10))="AUSTRALIA"),"Australia",IF(OR(UPPER(TRIM(E10))="CAN",UPPER(TRIM(E10))="CANADA"),"Canada",IF(OR(UPPER(TRIM(E10))="DE",UPPER(TRIM(E10))="GERMANY"),"Germany",IF(OR(UPPER(TRIM(E10))="IN",UPPER(TRIM(E10))="INDIA"),"India",IF(OR(UPPER(TRIM(E10))="US",UPPER(TRIM(E10))="USA",UPPER(TRIM(E10))="UNITED STATES"),"United States",IF(OR(UPPER(TRIM(E10))="UK",UPPER(TRIM(E10))="U.K.",UPPER(TRIM(E10))="UNITED KINGDOM"),"United Kingdom",IF(OR(UPPER(TRIM(E10))="UAE",UPPER(TRIM(E10))="U.A.E.",UPPER(TRIM(E10))="UNITED ARAB EMIRATES"),"United Arab Emirates",IF(OR(UPPER(TRIM(E10))="SG",UPPER(TRIM(E10))="SINGAPORE"),"Singapore",TRIM(E10))))))))) -> Singapore | G10: USB-C Hub | H10: Accessories | I10: 3 | J10: 42 | K10: 21 | L10: 0.05 | M10: paypal | N10: PayPal | O10: Cancelled | P10: =PROPER(TRIM(O10)) -> Cancelled | Q10: =IF(TRIM(R10)="","Missing",IF(AND(ISNUMBER(SEARCH("@",R10)),ISNUMBER(SEARCH(".",R10,SEARCH("@",R10)+2))),"Valid","Invalid")) -> Valid | R10: grace.moore@example.com | S10: =I10*J10*(1-L10) -> 119.7 | T10: =I10*K10 -> 63 | U10: =S10-T10 -> 56.7 | V10: =IF(S10=0,0,U10/S10) -> 0.47368421
A11: ORD-10011 | B11: 45914 | C11: Henry Clark | D11: =PROPER(TRIM(C11)) -> Henry Clark | E11: CAN | F11: =IF(OR(UPPER(TRIM(E11))="AUS",UPPER(TRIM(E11))="AUSTRALIA"),"Australia",IF(OR(UPPER(TRIM(E11))="CAN",UPPER(TRIM(E11))="CANADA"),"Canada",IF(OR(UPPER(TRIM(E11))="DE",UPPER(TRIM(E11))="GERMANY"),"Germany",IF(OR(UPPER(TRIM(E11))="IN",UPPER(TRIM(E11))="INDIA"),"India",IF(OR(UPPER(TRIM(E11))="US",UPPER(TRIM(E11))="USA",UPPER(TRIM(E11))="UNITED STATES"),"United States",IF(OR(UPPER(TRIM(E11))="UK",UPPER(TRIM(E11))="U.K.",UPPER(TRIM(E11))="UNITED KINGDOM"),"United Kingdom",IF(OR(UPPER(TRIM(E11))="UAE",UPPER(TRIM(E11))="U.A.E.",UPPER(TRIM(E11))="UNITED ARAB EMIRATES"),"United Arab Emirates",IF(OR(UPPER(TRIM(E11))="SG",UPPER(TRIM(E11))="SINGAPORE"),"Singapore",TRIM(E11))))))))) -> Canada | G11: Office Chair | H11: Furniture | I11: 1 | J11: 210 | K11: 125 | L11: 0.05 | M11: PayPal | N11: PayPal | O11: Cancelled | P11: =PROPER(TRIM(O11)) -> Cancelled | Q11: =IF(TRIM(R11)="","Missing",IF(AND(ISNUMBER(SEARCH("@",R11)),ISNUMBER(SEARCH(".",R11,SEARCH("@",R11)+2))),"Valid","Invalid")) -> Valid | R11: henry.clark@example.com | S11: =I11*J11*(1-L11) -> 199.5 | T11: =I11*K11 -> 125 | U11: =S11-T11 -> 74.5 | V11: =IF(S11=0,0,U11/S11) -> 0.37343358
A12: ORD-10049 | B12: 45801 | C12: Olivia Davis | D12: =PROPER(TRIM(C12)) -> Olivia Davis | E12: DE | F12: =IF(OR(UPPER(TRIM(E12))="AUS",UPPER(TRIM(E12))="AUSTRALIA"),"Australia",IF(OR(UPPER(TRIM(E12))="CAN",UPPER(TRIM(E12))="CANADA"),"Canada",IF(OR(UPPER(TRIM(E12))="DE",UPPER(TRIM(E12))="GERMANY"),"Germany",IF(OR(UPPER(TRIM(E12))="IN",UPPER(TRIM(E12))="INDIA"),"India",IF(OR(UPPER(TRIM(E12))="US",UPPER(TRIM(E12))="USA",UPPER(TRIM(E12))="UNITED STATES"),"United States",IF(OR(UPPER(TRIM(E12))="UK",UPPER(TRIM(E12))="U.K.",UPPER(TRIM(E12))="UNITED KINGDOM"),"United Kingdom",IF(OR(UPPER(TRIM(E12))="UAE",UPPER(TRIM(E12))="U.A.E.",UPPER(TRIM(E12))="UNITED ARAB EMIRATES"),"United Arab Emirates",IF(OR(UPPER(TRIM(E12))="SG",UPPER(TRIM(E12))="SINGAPORE"),"Singapore",TRIM(E12))))))))) -> Germany | G12: Webcam | H12: Electronics | I12: 3 | J12: 59 | K12: 30 | L12: 0.05 | M12: credit card | N12: =PROPER(TRIM(M12)) -> Credit Card | O12: Completed | P12: =PROPER(TRIM(O12)) -> Completed | Q12: =IF(TRIM(R12)="","Missing",IF(AND(ISNUMBER(SEARCH("@",R12)),ISNUMBER(SEARCH(".",R12,SEARCH("@",R12)+2))),"Valid","Invalid")) -> Valid | R12: olivia.davis@example.com | S12: =I12*J12*(1-L12) -> 168.15 | T12: =I12*K12 -> 90 | U12: =S12-T12 -> 78.15 | V12: =IF(S12=0,0,U12/S12) -> 0.4647636
A13: ORD-10215 | B13: 45918 | C13: Daniel Harris | D13: =PROPER(TRIM(C13)) -> Daniel Harris | E13: SG | F13: =IF(OR(UPPER(TRIM(E13))="AUS",UPPER(TRIM(E13))="AUSTRALIA"),"Australia",IF(OR(UPPER(TRIM(E13))="CAN",UPPER(TRIM(E13))="CANADA"),"Canada",IF(OR(UPPER(TRIM(E13))="DE",UPPER(TRIM(E13))="GERMANY"),"Germany",IF(OR(UPPER(TRIM(E13))="IN",UPPER(TRIM(E13))="INDIA"),"India",IF(OR(UPPER(TRIM(E13))="US",UPPER(TRIM(E13))="USA",UPPER(TRIM(E13))="UNITED STATES"),"United States",IF(OR(UPPER(TRIM(E13))="UK",UPPER(TRIM(E13))="U.K.",UPPER(TRIM(E13))="UNITED KINGDOM"),"United Kingdom",IF(OR(UPPER(TRIM(E13))="UAE",UPPER(TRIM(E13))="U.A.E.",UPPER(TRIM(E13))="UNITED ARAB EMIRATES"),"United Arab Emirates",IF(OR(UPPER(TRIM(E13))="SG",UPPER(TRIM(E13))="SINGAPORE"),"Singapore",TRIM(E13))))))))) -> Singapore | G13: USB-C Hub | H13: Accessories | I13: 3 | J13: 42 | K13: 21 | L13: 0 | M13: paypal | N13: PayPal | O13: Pending | P13: =PROPER(TRIM(O13)) -> Pending | Q13: =IF(TRIM(R13)="","Missing",IF(AND(ISNUMBER(SEARCH("@",R13)),ISNUMBER(SEARCH(".",R13,SEARCH("@",R13)+2))),"Valid","Invalid")) -> Valid | R13: daniel.harris@example.com | S13: =I13*J13*(1-L13) -> 126 | T13: =I13*K13 -> 63 | U13: =S13-T13 -> 63 | V13: =IF(S13=0,0,U13/S13) -> 0.5
A14: ORD-10333 | B14: 45830 | C14: Noah Brown | D14: =PROPER(TRIM(C14)) -> Noah Brown | E14: germany | F14: =IF(OR(UPPER(TRIM(E14))="AUS",UPPER(TRIM(E14))="AUSTRALIA"),"Australia",IF(OR(UPPER(TRIM(E14))="CAN",UPPER(TRIM(E14))="CANADA"),"Canada",IF(OR(UPPER(TRIM(E14))="DE",UPPER(TRIM(E14))="GERMANY"),"Germany",IF(OR(UPPER(TRIM(E14))="IN",UPPER(TRIM(E14))="INDIA"),"India",IF(OR(UPPER(TRIM(E14))="US",UPPER(TRIM(E14))="USA",UPPER(TRIM(E14))="UNITED STATES"),"United States",IF(OR(UPPER(TRIM(E14))="UK",UPPER(TRIM(E14))="U.K.",UPPER(TRIM(E14))="UNITED KINGDOM"),"United Kingdom",IF(OR(UPPER(TRIM(E14))="UAE",UPPER(TRIM(E14))="U.A.E.",UPPER(TRIM(E14))="UNITED ARAB EMIRATES"),"United Arab Emirates",IF(OR(UPPER(TRIM(E14))="SG",UPPER(TRIM(E14))="SINGAPORE"),"Singapore",TRIM(E14))))))))) -> Germany | G14: Headphones | H14: Electronics | I14: 3 | J14: 85 | K14: 44 | L14: 0 | M14: Debit Card | N14: =PROPER(TRIM(M14)) -> Debit Card | O14: Completed | P14: =PROPER(TRIM(O14)) -> Completed | Q14: =IF(TRIM(R14)="","Missing",IF(AND(ISNUMBER(SEARCH("@",R14)),ISNUMBER(SEARCH(".",R14,SEARCH("@",R14)+2))),"Valid","Invalid")) -> Valid | R14: noah.brown@example.com | S14: =I14*J14*(1-L14) -> 255 | T14: =I14*K14 -> 132 | U14: =S14-T14 -> 123 | V14: =IF(S14=0,0,U14/S14) -> 0.48235294
A15: ORD-10531 | B15: 45825 | C15: Henry Clark | D15: =PROPER(TRIM(C15)) -> Henry Clark | E15: India | F15: =IF(OR(UPPER(TRIM(E15))="AUS",UPPER(TRIM(E15))="AUSTRALIA"),"Australia",IF(OR(UPPER(TRIM(E15))="CAN",UPPER(TRIM(E15))="CANADA"),"Canada",IF(OR(UPPER(TRIM(E15))="DE",UPPER(TRIM(E15))="GERMANY"),"Germany",IF(OR(UPPER(TRIM(E15))="IN",UPPER(TRIM(E15))="INDIA"),"India",IF(OR(UPPER(TRIM(E15))="US",UPPER(TRIM(E15))="USA",UPPER(TRIM(E15))="UNITED STATES"),"United States",IF(OR(UPPER(TRIM(E15))="UK",UPPER(TRIM(E15))="U.K.",UPPER(TRIM(E15))="UNITED KINGDOM"),"United Kingdom",IF(OR(UPPER(TRIM(E15))="UAE",UPPER(TRIM(E15))="U.A.E.",UPPER(TRIM(E15))="UNITED ARAB EMIRATES"),"United Arab Emirates",IF(OR(UPPER(TRIM(E15))="SG",UPPER(TRIM(E15))="SINGAPORE"),"Singapore",TRIM(E15))))))))) -> India | G15: Desk Lamp | H15: Furniture | I15: 4 | J15: 36 | K15: 16 | L15: 0 | M15: credit card | N15: =PROPER(TRIM(M15)) -> Credit Card | O15: Completed | P15: =PROPER(TRIM(O15)) -> Completed | Q15: =IF(TRIM(R15)="","Missing",IF(AND(ISNUMBER(SEARCH("@",R15)),ISNUMBER(SEARCH(".",R15,SEARCH("@",R15)+2))),"Valid","Invalid")) -> Valid | R15: henry.clark@example.com | S15: =I15*J15*(1-L15) -> 144 | T15: =I15*K15 -> 64 | U15: =S15-T15 -> 80 | V15: =IF(S15=0,0,U15/S15) -> 0.55555556
A16: ORD-10341 | B16: 45795 | C16: sophia taylor | D16: =PROPER(TRIM(C16)) -> Sophia Taylor | E16: singapore | F16: =IF(OR(UPPER(TRIM(E16))="AUS",UPPER(TRIM(E16))="AUSTRALIA"),"Australia",IF(OR(UPPER(TRIM(E16))="CAN",UPPER(TRIM(E16))="CANADA"),"Canada",IF(OR(UPPER(TRIM(E16))="DE",UPPER(TRIM(E16))="GERMANY"),"Germany",IF(OR(UPPER(TRIM(E16))="IN",UPPER(TRIM(E16))="INDIA"),"India",IF(OR(UPPER(TRIM(E16))="US",UPPER(TRIM(E16))="USA",UPPER(TRIM(E16))="UNITED STATES"),"United States",IF(OR(UPPER(TRIM(E16))="UK",UPPER(TRIM(E16))="U.K.",UPPER(TRIM(E16))="UNITED KINGDOM"),"United Kingdom",IF(OR(UPPER(TRIM(E16))="UAE",UPPER(TRIM(E16))="U.A.E.",UPPER(TRIM(E16))="UNITED ARAB EMIRATES"),"United Arab Emirates",IF(OR(UPPER(TRIM(E16))="SG",UPPER(TRIM(E16))="SINGAPORE"),"Singapore",TRIM(E16))))))))) -> Singapore | G16: Webcam | H16: Electronics | I16: 5 | J16: 59 | K16: 30 | L16: 0.1 | M16: credit card | N16: =PROPER(TRIM(M16)) -> Credit Card | O16: Pending | P16: =PROPER(TRIM(O16)) -> Pending | Q16: =IF(TRIM(R16)="","Missing",IF(AND(ISNUMBER(SEARCH("@",R16)),ISNUMBER(SEARCH(".",R16,SEARCH("@",R16)+2))),"Valid","Invalid")) -> Valid | R16: sophia.taylor@example.com | S16: =I16*J16*(1-L16) -> 265.5 | T16: =I16*K16 -> 150 | U16: =S16-T16 -> 115.5 | V16: =IF(S16=0,0,U16/S16) -> 0.43502825
A17: ORD-10054 | B17: 46018 | C17: Ava Thomas | D17: =PROPER(TRIM(C17)) -> Ava Thomas | E17: United Arab Emirates | F17: =IF(OR(UPPER(TRIM(E17))="AUS",UPPER(TRIM(E17))="AUSTRALIA"),"Australia",IF(OR(UPPER(TRIM(E17))="CAN",UPPER(TRIM(E17))="CANADA"),"Canada",IF(OR(UPPER(TRIM(E17))="DE",UPPER(TRIM(E17))="GERMANY"),"Germany",IF(OR(UPPER(TRIM(E17))="IN",UPPER(TRIM(E17))="INDIA"),"India",IF(OR(UPPER(TRIM(E17))="US",UPPER(TRIM(E17))="USA",UPPER(TRIM(E17))="UNITED STATES"),"United States",IF(OR(UPPER(TRIM(E17))="UK",UPPER(TRIM(E17))="U.K.",UPPER(TRIM(E17))="UNITED KINGDOM"),"United Kingdom",IF(OR(UPPER(TRIM(E17))="UAE",UPPER(TRIM(E17))="U.A.E.",UPPER(TRIM(E17))="UNITED ARAB EMIRATES"),"United Arab Emirates",IF(OR(UPPER(TRIM(E17))="SG",UPPER(TRIM(E17))="SINGAPORE"),"Singapore",TRIM(E17))))))))) -> United Arab Emirates | G17: Desk Lamp | H17: Furniture | I17: 2 | J17: 36 | K17: 16 | L17: 0.1 | M17: Bank Transfer | N17: =PROPER(TRIM(M17)) -> Bank Transfer | O17: Completed | P17: =PROPER(TRIM(O17)) -> Completed | Q17: =IF(TRIM(R17)="","Missing",IF(AND(ISNUMBER(SEARCH("@",R17)),ISNUMBER(SEARCH(".",R17,SEARCH("@",R17)+2))),"Valid","Invalid")) -> Valid | R17: ava.thomas@example.com | S17: =I17*J17*(1-L17) -> 64.8 | T17: =I17*K17 -> 32 | U17: =S17-T17 -> 32.8 | V17: =IF(S17=0,0,U17/S17) -> 0.50617284
A18: ORD-10065 | B18: 45908 | C18: Liam Miller | D18: =PROPER(TRIM(C18)) -> Liam Miller | E18: australia | F18: =IF(OR(UPPER(TRIM(E18))="AUS",UPPER(TRIM(E18))="AUSTRALIA"),"Australia",IF(OR(UPPER(TRIM(E18))="CAN",UPPER(TRIM(E18))="CANADA"),"Canada",IF(OR(UPPER(TRIM(E18))="DE",UPPER(TRIM(E18))="GERMANY"),"Germany",IF(OR(UPPER(TRIM(E18))="IN",UPPER(TRIM(E18))="INDIA"),"India",IF(OR(UPPER(TRIM(E18))="US",UPPER(TRIM(E18))="USA",UPPER(TRIM(E18))="UNITED STATES"),"United States",IF(OR(UPPER(TRIM(E18))="UK",UPPER(TRIM(E18))="U.K.",UPPER(TRIM(E18))="UNITED KINGDOM"),"United Kingdom",IF(OR(UPPER(TRIM(E18))="UAE",UPPER(TRIM(E18))="U.A.E.",UPPER(TRIM(E18))="UNITED ARAB EMIRATES"),"United Arab Emirates",IF(OR(UPPER(TRIM(E18))="SG",UPPER(TRIM(E18))="SINGAPORE"),"Singapore",TRIM(E18))))))))) -> Australia | G18: Mechanical Keyboard | H18: Accessories | I18: 1 | J18: 65 | K18: 31 | L18: 0.05 | M18: Credit Card | N18: =PROPER(TRIM(M18)) -> Credit Card | O18: Completed | P18: =PROPER(TRIM(O18)) -> Completed | Q18: =IF(TRIM(R18)="","Missing",IF(AND(ISNUMBER(SEARCH("@",R18)),ISNUMBER(SEARCH(".",R18,SEARCH("@",R18)+2))),"Valid","Invalid")) -> Valid | R18: liam.miller@example.com | S18: =I18*J18*(1-L18) -> 61.75 | T18: =I18*K18 -> 31 | U18: =S18-T18 -> 30.75 | V18: =IF(S18=0,0,U18/S18) -> 0.49797571
A19: ORD-10072 | B19: 45704 | C19: Lucas Jackson | D19: =PROPER(TRIM(C19)) -> Lucas Jackson | E19: USA | F19: =IF(OR(UPPER(TRIM(E19))="AUS",UPPER(TRIM(E19))="AUSTRALIA"),"Australia",IF(OR(UPPER(TRIM(E19))="CAN",UPPER(TRIM(E19))="CANADA"),"Canada",IF(OR(UPPER(TRIM(E19))="DE",UPPER(TRIM(E19))="GERMANY"),"Germany",IF(OR(UPPER(TRIM(E19))="IN",UPPER(TRIM(E19))="INDIA"),"India",IF(OR(UPPER(TRIM(E19))="US",UPPER(TRIM(E19))="USA",UPPER(TRIM(E19))="UNITED STATES"),"United States",IF(OR(UPPER(TRIM(E19))="UK",UPPER(TRIM(E19))="U.K.",UPPER(TRIM(E19))="UNITED KINGDOM"),"United Kingdom",IF(OR(UPPER(TRIM(E19))="UAE",UPPER(TRIM(E19))="U.A.E.",UPPER(TRIM(E19))="UNITED ARAB EMIRATES"),"United Arab Emirates",IF(OR(UPPER(TRIM(E19))="SG",UPPER(TRIM(E19))="SINGAPORE"),"Singapore",TRIM(E19))))))))) -> United States | G19: Mechanical Keyboard | H19: Accessories | I19: 2 | J19: 65 | K19: 31 | L19: 0.1 | M19: paypal | N19: PayPal | O19: Completed | P19: =PROPER(TRIM(O19)) -> Completed | Q19: =IF(TRIM(R19)="","Missing",IF(AND(ISNUMBER(SEARCH("@",R19)),ISNUMBER(SEARCH(".",R19,SEARCH("@",R19)+2))),"Valid","Invalid")) -> Valid | R19: lucas.jackson@example.com | S19: =I19*J19*(1-L19) -> 117 | T19: =I19*K19 -> 62 | U19: =S19-T19 -> 55 | V19: =IF(S19=0,0,U19/S19) -> 0.47008547
A20: ORD-10033 | B20: 45979 | C20: Henry Clark | D20: =PROPER(TRIM(C20)) -> Henry Clark | E20: US | F20: =IF(OR(UPPER(TRIM(E20))="AUS",UPPER(TRIM(E20))="AUSTRALIA"),"Australia",IF(OR(UPPER(TRIM(E20))="CAN",UPPER(TRIM(E20))="CANADA"),"Canada",IF(OR(UPPER(TRIM(E20))="DE",UPPER(TRIM(E20))="GERMANY"),"Germany",IF(OR(UPPER(TRIM(E20))="IN",UPPER(TRIM(E20))="INDIA"),"India",IF(OR(UPPER(TRIM(E20))="US",UPPER(TRIM(E20))="USA",UPPER(TRIM(E20))="UNITED STATES"),"United States",IF(OR(UPPER(TRIM(E20))="UK",UPPER(TRIM(E20))="U.K.",UPPER(TRIM(E20))="UNITED KINGDOM"),"United Kingdom",IF(OR(UPPER(TRIM(E20))="UAE",UPPER(TRIM(E20))="U.A.E.",UPPER(TRIM(E20))="UNITED ARAB EMIRATES"),"United Arab Emirates",IF(OR(UPPER(TRIM(E20))="SG",UPPER(TRIM(E20))="SINGAPORE"),"Singapore",TRIM(E20))))))))) -> United States | G20: Laptop Stand | H20: Accessories | I20: 4 | J20: 38 | K20: 17 | L20: 0.15 | M20: Bank Transfer | N20: =PROPER(TRIM(M20)) -> Bank Transfer | O20: Pending | P20: =PROPER(TRIM(O20)) -> Pending | Q20: =IF(TRIM(R20)="","Missing",IF(AND(ISNUMBER(SEARCH("@",R20)),ISNUMBER(SEARCH(".",R20,SEARCH("@",R20)+2))),"Valid","Invalid")) -> Missing | S20: =I20*J20*(1-L20) -> 129.2 | T20: =I20*K20 -> 68 | U20: =S20-T20 -> 61.2 | V20: =IF(S20=0,0,U20/S20) -> 0.47368421
A21: ORD-10264 | B21: 45815 | C21: Chloe Lewis | D21: =PROPER(TRIM(C21)) -> Chloe Lewis | E21: DE | F21: =IF(OR(UPPER(TRIM(E21))="AUS",UPPER(TRIM(E21))="AUSTRALIA"),"Australia",IF(OR(UPPER(TRIM(E21))="CAN",UPPER(TRIM(E21))="CANADA"),"Canada",IF(OR(UPPER(TRIM(E21))="DE",UPPER(TRIM(E21))="GERMANY"),"Germany",IF(OR(UPPER(TRIM(E21))="IN",UPPER(TRIM(E21))="INDIA"),"India",IF(OR(UPPER(TRIM(E21))="US",UPPER(TRIM(E21))="USA",UPPER(TRIM(E21))="UNITED STATES"),"United States",IF(OR(UPPER(TRIM(E21))="UK",UPPER(TRIM(E21))="U.K.",UPPER(TRIM(E21))="UNITED KINGDOM"),"United Kingdom",IF(OR(UPPER(TRIM(E21))="UAE",UPPER(TRIM(E21))="U.A.E.",UPPER(TRIM(E21))="UNITED ARAB EMIRATES"),"United Arab Emirates",IF(OR(UPPER(TRIM(E21))="SG",UPPER(TRIM(E21))="SINGAPORE"),"Singapore",TRIM(E21))))))))) -> Germany | G21: SSD 1TB | H21: Storage | I21: 1 | J21: 92 | K21: 53 | L21: 0.2 | M21: Bank Transfer | N21: =PROPER(TRIM(M21)) -> Bank Transfer | O21: Shipped | P21: =PROPER(TRIM(O21)) -> Shipped | Q21: =IF(TRIM(R21)="","Missing",IF(AND(ISNUMBER(SEARCH("@",R21)),ISNUMBER(SEARCH(".",R21,SEARCH("@",R21)+2))),"Valid","Invalid")) -> Valid | R21: chloe.lewis@example.com | S21: =I21*J21*(1-L21) -> 73.6 | T21: =I21*K21 -> 53 | U21: =S21-T21 -> 20.6 | V21: =IF(S21=0,0,U21/S21) -> 0.2798913
A22: ORD-10210 | B22: 45889 | C22: Chloe Lewis | D22: =PROPER(TRIM(C22)) -> Chloe Lewis | E22: United Kingdom | F22: =IF(OR(UPPER(TRIM(E22))="AUS",UPPER(TRIM(E22))="AUSTRALIA"),"Australia",IF(OR(UPPER(TRIM(E22))="CAN",UPPER(TRIM(E22))="CANADA"),"Canada",IF(OR(UPPER(TRIM(E22))="DE",UPPER(TRIM(E22))="GERMANY"),"Germany",IF(OR(UPPER(TRIM(E22))="IN",UPPER(TRIM(E22))="INDIA"),"India",IF(OR(UPPER(TRIM(E22))="US",UPPER(TRIM(E22))="USA",UPPER(TRIM(E22))="UNITED STATES"),"United States",IF(OR(UPPER(TRIM(E22))="UK",UPPER(TRIM(E22))="U.K.",UPPER(TRIM(E22))="UNITED KINGDOM"),"United Kingdom",IF(OR(UPPER(TRIM(E22))="UAE",UPPER(TRIM(E22))="U.A.E.",UPPER(TRIM(E22))="UNITED ARAB EMIRATES"),"United Arab Emirates",IF(OR(UPPER(TRIM(E22))="SG",UPPER(TRIM(E22))="SINGAPORE"),"Singapore",TRIM(E22))))))))) -> United Kingdom | G22: Webcam | H22: Electronics | I22: 4 | J22: 59 | K22: 30 | L22: 0.15 | M22: Credit Card | N22: =PROPER(TRIM(M22)) -> Credit Card | O22: Completed | P22: =PROPER(TRIM(O22)) -> Completed | Q22: =IF(TRIM(R22)="","Missing",IF(AND(ISNUMBER(SEARCH("@",R22)),ISNUMBER(SEARCH(".",R22,SEARCH("@",R22)+2))),"Valid","Invalid")) -> Missing | S22: =I22*J22*(1-L22) -> 200.6 | T22: =I22*K22 -> 120 | U22: =S22-T22 -> 80.6 | V22: =IF(S22=0,0,U22/S22) -> 0.40179462
A23: ORD-10274 | B23: 45831 | C23: Ava Thomas | D23: =PROPER(TRIM(C23)) -> Ava Thomas | E23: Singapore | F23: =IF(OR(UPPER(TRIM(E23))="AUS",UPPER(TRIM(E23))="AUSTRALIA"),"Australia",IF(OR(UPPER(TRIM(E23))="CAN",UPPER(TRIM(E23))="CANADA"),"Canada",IF(OR(UPPER(TRIM(E23))="DE",UPPER(TRIM(E23))="GERMANY"),"Germany",IF(OR(UPPER(TRIM(E23))="IN",UPPER(TRIM(E23))="INDIA"),"India",IF(OR(UPPER(TRIM(E23))="US",UPPER(TRIM(E23))="USA",UPPER(TRIM(E23))="UNITED STATES"),"United States",IF(OR(UPPER(TRIM(E23))="UK",UPPER(TRIM(E23))="U.K.",UPPER(TRIM(E23))="UNITED KINGDOM"),"United Kingdom",IF(OR(UPPER(TRIM(E23))="UAE",UPPER(TRIM(E23))="U.A.E.",UPPER(TRIM(E23))="UNITED ARAB EMIRATES"),"United Arab Emirates",IF(OR(UPPER(TRIM(E23))="SG",UPPER(TRIM(E23))="SINGAPORE"),"Singapore",TRIM(E23))))))))) -> Singapore | G23: External HDD 2TB | H23: Storage | I23: 4 | J23: 78 | K23: 45 | L23: 0.1 | N23: Unknown | O23: Pending | P23: =PROPER(TRIM(O23)) -> Pending | Q23: =IF(TRIM(R23)="","Missing",IF(AND(ISNUMBER(SEARCH("@",R23)),ISNUMBER(SEARCH(".",R23,SEARCH("@",R23)+2))),"Valid","Invalid")) -> Valid | R23: ava.thomas@example.com | S23: =I23*J23*(1-L23) -> 280.8 | T23: =I23*K23 -> 180 | U23: =S23-T23 -> 100.8 | V23: =IF(S23=0,0,U23/S23) -> 0.35897436
A24: ORD-10004 | B24: 45792 | C24: Noah Brown | D24: =PROPER(TRIM(C24)) -> Noah Brown | E24: Australia | F24: =IF(OR(UPPER(TRIM(E24))="AUS",UPPER(TRIM(E24))="AUSTRALIA"),"Australia",IF(OR(UPPER(TRIM(E24))="CAN",UPPER(TRIM(E24))="CANADA"),"Canada",IF(OR(UPPER(TRIM(E24))="DE",UPPER(TRIM(E24))="GERMANY"),"Germany",IF(OR(UPPER(TRIM(E24))="IN",UPPER(TRIM(E24))="INDIA"),"India",IF(OR(UPPER(TRIM(E24))="US",UPPER(TRIM(E24))="USA",UPPER(TRIM(E24))="UNITED STATES"),"United States",IF(OR(UPPER(TRIM(E24))="UK",UPPER(TRIM(E24))="U.K.",UPPER(TRIM(E24))="UNITED KINGDOM"),"United Kingdom",IF(OR(UPPER(TRIM(E24))="UAE",UPPER(TRIM(E24))="U.A.E.",UPPER(TRIM(E24))="UNITED ARAB EMIRATES"),"United Arab Emirates",IF(OR(UPPER(TRIM(E24))="SG",UPPER(TRIM(E24))="SINGAPORE"),"Singapore",TRIM(E24))))))))) -> Australia | G24: USB-C Hub | H24: Accessories | I24: 4 | J24: 42 | K24: 21 | L24: 0.05 | M24: Credit Card | N24: =PROPER(TRIM(M24)) -> Credit Card | O24: Cancelled | P24: =PROPER(TRIM(O24)) -> Cancelled | Q24: =IF(TRIM(R24)="","Missing",IF(AND(ISNUMBER(SEARCH("@",R24)),ISNUMBER(SEARCH(".",R24,SEARCH("@",R24)+2))),"Valid","Invalid")) -> Valid | R24: noah.brown@example.com | S24: =I24*J24*(1-L24) -> 159.6 | T24: =I24*K24 -> 84 | U24: =S24-T24 -> 75.6 | V24: =IF(S24=0,0,U24/S24) -> 0.47368421
A25: ORD-10200 | B25: 45933 | C25: Noah Brown | D25: =PROPER(TRIM(C25)) -> Noah Brown | E25: Canada | F25: =IF(OR(UPPER(TRIM(E25))="AUS",UPPER(TRIM(E25))="AUSTRALIA"),"Australia",IF(OR(UPPER(TRIM(E25))="CAN",UPPER(TRIM(E25))="CANADA"),"Canada",IF(OR(UPPER(TRIM(E25))="DE",UPPER(TRIM(E25))="GERMANY"),"Germany",IF(OR(UPPER(TRIM(E25))="IN",UPPER(TRIM(E25))="INDIA"),"India",IF(OR(UPPER(TRIM(E25))="US",UPPER(TRIM(E25))="USA",UPPER(TRIM(E25))="UNITED STATES"),"United States",IF(OR(UPPER(TRIM(E25))="UK",UPPER(TRIM(E25))="U.K.",UPPER(TRIM(E25))="UNITED KINGDOM"),"United Kingdom",IF(OR(UPPER(TRIM(E25))="UAE",UPPER(TRIM(E25))="U.A.E.",UPPER(TRIM(E25))="UNITED ARAB EMIRATES"),"United Arab Emirates",IF(OR(UPPER(TRIM(E25))="SG",UPPER(TRIM(E25))="SINGAPORE"),"Singapore",TRIM(E25))))))))) -> Canada | G25: Webcam | H25: Electronics | I25: 2 | J25: 59 | K25: 30 | L25: 0 | M25: PayPal | N25: PayPal | O25: Completed | P25: =PROPER(TRIM(O25)) -> Completed | Q25: =IF(TRIM(R25)="","Missing",IF(AND(ISNUMBER(SEARCH("@",R25)),ISNUMBER(SEARCH(".",R25,SEARCH("@",R25)+2))),"Valid","Invalid")) -> Valid | R25: noah.brown@example.com | S25: =I25*J25*(1-L25) -> 118 | T25: =I25*K25 -> 60 | U25: =S25-T25 -> 58 | V25: =IF(S25=0,0,U25/S25) -> 0.49152542
A26: ORD-10191 | B26: 45684 | C26: Emma Wilson | D26: =PROPER(TRIM(C26)) -> Emma Wilson | E26: US | F26: =IF(OR(UPPER(TRIM(E26))="AUS",UPPER(TRIM(E26))="AUSTRALIA"),"Australia",IF(OR(UPPER(TRIM(E26))="CAN",UPPER(TRIM(E26))="CANADA"),"Canada",IF(OR(UPPER(TRIM(E26))="DE",UPPER(TRIM(E26))="GERMANY"),"Germany",IF(OR(UPPER(TRIM(E26))="IN",UPPER(TRIM(E26))="INDIA"),"India",IF(OR(UPPER(TRIM(E26))="US",UPPER(TRIM(E26))="USA",UPPER(TRIM(E26))="UNITED STATES"),"United States",IF(OR(UPPER(TRIM(E26))="UK",UPPER(TRIM(E26))="U.K.",UPPER(TRIM(E26))="UNITED KINGDOM"),"United Kingdom",IF(OR(UPPER(TRIM(E26))="UAE",UPPER(TRIM(E26))="U.A.E.",UPPER(TRIM(E26))="UNITED ARAB EMIRATES"),"United Arab Emirates",IF(OR(UPPER(TRIM(E26))="SG",UPPER(TRIM(E26))="SINGAPORE"),"Singapore",TRIM(E26))))))))) -> United States | G26: Headphones | H26: Electronics | I26: 4 | J26: 85 | K26: 44 | L26: 0.05 | M26: paypal | N26: PayPal | O26: Cancelled | P26: =PROPER(TRIM(O26)) -> Cancelled | Q26: =IF(TRIM(R26)="","Missing",IF(AND(ISNUMBER(SEARCH("@",R26)),ISNUMBER(SEARCH(".",R26,SEARCH("@",R26)+2))),"Valid","Invalid")) -> Valid | R26: emma.wilson@example.com | S26: =I26*J26*(1-L26) -> 323 | T26: =I26*K26 -> 176 | U26: =S26-T26 -> 147 | V26: =IF(S26=0,0,U26/S26) -> 0.45510836
A27: ORD-10266 | B27: 45733 | C27: Henry Clark | D27: =PROPER(TRIM(C27)) -> Henry Clark | E27: India | F27: =IF(OR(UPPER(TRIM(E27))="AUS",UPPER(TRIM(E27))="AUSTRALIA"),"Australia",IF(OR(UPPER(TRIM(E27))="CAN",UPPER(TRIM(E27))="CANADA"),"Canada",IF(OR(UPPER(TRIM(E27))="DE",UPPER(TRIM(E27))="GERMANY"),"Germany",IF(OR(UPPER(TRIM(E27))="IN",UPPER(TRIM(E27))="INDIA"),"India",IF(OR(UPPER(TRIM(E27))="US",UPPER(TRIM(E27))="USA",UPPER(TRIM(E27))="UNITED STATES"),"United States",IF(OR(UPPER(TRIM(E27))="UK",UPPER(TRIM(E27))="U.K.",UPPER(TRIM(E27))="UNITED KINGDOM"),"United Kingdom",IF(OR(UPPER(TRIM(E27))="UAE",UPPER(TRIM(E27))="U.A.E.",UPPER(TRIM(E27))="UNITED ARAB EMIRATES"),"United Arab Emirates",IF(OR(UPPER(TRIM(E27))="SG",UPPER(TRIM(E27))="SINGAPORE"),"Singapore",TRIM(E27))))))))) -> India | G27: Mechanical Keyboard | H27: Accessories | I27: 1 | J27: 65 | K27: 31 | L27: 0 | M27: Credit Card | N27: =PROPER(TRIM(M27)) -> Credit Card | O27: Pending | P27: =PROPER(TRIM(O27)) -> Pending | Q27: =IF(TRIM(R27)="","Missing",IF(AND(ISNUMBER(SEARCH("@",R27)),ISNUMBER(SEARCH(".",R27,SEARCH("@",R27)+2))),"Valid","Invalid")) -> Valid | R27: henry.clark@example.com | S27: =I27*J27*(1-L27) -> 65 | T27: =I27*K27 -> 31 | U27: =S27-T27 -> 34 | V27: =IF(S27=0,0,U27/S27) -> 0.52307692
A28: ORD-10280 | B28: 45852 | C28: Ella Martin | D28: =PROPER(TRIM(C28)) -> Ella Martin | E28: germany | F28: =IF(OR(UPPER(TRIM(E28))="AUS",UPPER(TRIM(E28))="AUSTRALIA"),"Australia",IF(OR(UPPER(TRIM(E28))="CAN",UPPER(TRIM(E28))="CANADA"),"Canada",IF(OR(UPPER(TRIM(E28))="DE",UPPER(TRIM(E28))="GERMANY"),"Germany",IF(OR(UPPER(TRIM(E28))="IN",UPPER(TRIM(E28))="INDIA"),"India",IF(OR(UPPER(TRIM(E28))="US",UPPER(TRIM(E28))="USA",UPPER(TRIM(E28))="UNITED STATES"),"United States",IF(OR(UPPER(TRIM(E28))="UK",UPPER(TRIM(E28))="U.K.",UPPER(TRIM(E28))="UNITED KINGDOM"),"United Kingdom",IF(OR(UPPER(TRIM(E28))="UAE",UPPER(TRIM(E28))="U.A.E.",UPPER(TRIM(E28))="UNITED ARAB EMIRATES"),"United Arab Emirates",IF(OR(UPPER(TRIM(E28))="SG",UPPER(TRIM(E28))="SINGAPORE"),"Singapore",TRIM(E28))))))))) -> Germany | G28: SSD 1TB | H28: Storage | I28: 2 | J28: 92 | K28: 53 | L28: 0.05 | M28: Debit Card | N28: =PROPER(TRIM(M28)) -> Debit Card | O28: Shipped | P28: =PROPER(TRIM(O28)) -> Shipped | Q28: =IF(TRIM(R28)="","Missing",IF(AND(ISNUMBER(SEARCH("@",R28)),ISNUMBER(SEARCH(".",R28,SEARCH("@",R28)+2))),"Valid","Invalid")) -> Valid | R28: ella.martin@example.com | S28: =I28*J28*(1-L28) -> 174.8 | T28: =I28*K28 -> 106 | U28: =S28-T28 -> 68.8 | V28: =IF(S28=0,0,U28/S28) -> 0.39359268
A29: ORD-10209 | B29: 45845 | C29: Olivia Davis | D29: =PROPER(TRIM(C29)) -> Olivia Davis | E29: U.K. | F29: =IF(OR(UPPER(TRIM(E29))="AUS",UPPER(TRIM(E29))="AUSTRALIA"),"Australia",IF(OR(UPPER(TRIM(E29))="CAN",UPPER(TRIM(E29))="CANADA"),"Canada",IF(OR(UPPER(TRIM(E29))="DE",UPPER(TRIM(E29))="GERMANY"),"Germany",IF(OR(UPPER(TRIM(E29))="IN",UPPER(TRIM(E29))="INDIA"),"India",IF(OR(UPPER(TRIM(E29))="US",UPPER(TRIM(E29))="USA",UPPER(TRIM(E29))="UNITED STATES"),"United States",IF(OR(UPPER(TRIM(E29))="UK",UPPER(TRIM(E29))="U.K.",UPPER(TRIM(E29))="UNITED KINGDOM"),"United Kingdom",IF(OR(UPPER(TRIM(E29))="UAE",UPPER(TRIM(E29))="U.A.E.",UPPER(TRIM(E29))="UNITED ARAB EMIRATES"),"United Arab Emirates",IF(OR(UPPER(TRIM(E29))="SG",UPPER(TRIM(E29))="SINGAPORE"),"Singapore",TRIM(E29))))))))) -> United Kingdom | G29: Webcam | H29: Electronics | I29: 5 | J29: 59 | K29: 30 | L29: 0.2 | M29: credit card | N29: =PROPER(TRIM(M29)) -> Credit Card | O29: Completed | P29: =PROPER(TRIM(O29)) -> Completed | Q29: =IF(TRIM(R29)="","Missing",IF(AND(ISNUMBER(SEARCH("@",R29)),ISNUMBER(SEARCH(".",R29,SEARCH("@",R29)+2))),"Valid","Invalid")) -> Valid | R29: olivia.davis@example.com | S29: =I29*J29*(1-L29) -> 236 | T29: =I29*K29 -> 150 | U29: =S29-T29 -> 86 | V29: =IF(S29=0,0,U29/S29) -> 0.36440678
A30: ORD-10028 | B30: 45706 | C30: olivia davis | D30: =PROPER(TRIM(C30)) -> Olivia Davis | E30: Germany | F30: =IF(OR(UPPER(TRIM(E30))="AUS",UPPER(TRIM(E30))="AUSTRALIA"),"Australia",IF(OR(UPPER(TRIM(E30))="CAN",UPPER(TRIM(E30))="CANADA"),"Canada",IF(OR(UPPER(TRIM(E30))="DE",UPPER(TRIM(E30))="GERMANY"),"Germany",IF(OR(UPPER(TRIM(E30))="IN",UPPER(TRIM(E30))="INDIA"),"India",IF(OR(UPPER(TRIM(E30))="US",UPPER(TRIM(E30))="USA",UPPER(TRIM(E30))="UNITED STATES"),"United States",IF(OR(UPPER(TRIM(E30))="UK",UPPER(TRIM(E30))="U.K.",UPPER(TRIM(E30))="UNITED KINGDOM"),"United Kingdom",IF(OR(UPPER(TRIM(E30))="UAE",UPPER(TRIM(E30))="U.A.E.",UPPER(TRIM(E30))="UNITED ARAB EMIRATES"),"United Arab Emirates",IF(OR(UPPER(TRIM(E30))="SG",UPPER(TRIM(E30))="SINGAPORE"),"Singapore",TRIM(E30))))))))) -> Germany | G30: Wireless Mouse | H30: Accessories | I30: 4 | J30: 18 | K30: 7 | L30: 0.1 | M30: Debit Card | N30: =PROPER(TRIM(M30)) -> Debit Card | O30: Completed | P30: =PROPER(TRIM(O30)) -> Completed | Q30: =IF(TRIM(R30)="","Missing",IF(AND(ISNUMBER(SEARCH("@",R30)),ISNUMBER(SEARCH(".",R30,SEARCH("@",R30)+2))),"Valid","Invalid")) -> Valid | R30: olivia.davis@example.com | S30: =I30*J30*(1-L30) -> 64.8 | T30: =I30*K30 -> 28 | U30: =S30-T30 -> 36.8 | V30: =IF(S30=0,0,U30/S30) -> 0.56790123
A31: ORD-10211 | B31: 45674 | C31: Benjamin Walker | D31: =PROPER(TRIM(C31)) -> Benjamin Walker | E31: united kingdom | F31: =IF(OR(UPPER(TRIM(E31))="AUS",UPPER(TRIM(E31))="AUSTRALIA"),"Australia",IF(OR(UPPER(TRIM(E31))="CAN",UPPER(TRIM(E31))="CANADA"),"Canada",IF(OR(UPPER(TRIM(E31))="DE",UPPER(TRIM(E31))="GERMANY"),"Germany",IF(OR(UPPER(TRIM(E31))="IN",UPPER(TRIM(E31))="INDIA"),"India",IF(OR(UPPER(TRIM(E31))="US",UPPER(TRIM(E31))="USA",UPPER(TRIM(E31))="UNITED STATES"),"United States",IF(OR(UPPER(TRIM(E31))="UK",UPPER(TRIM(E31))="U.K.",UPPER(TRIM(E31))="UNITED KINGDOM"),"United Kingdom",IF(OR(UPPER(TRIM(E31))="UAE",UPPER(TRIM(E31))="U.A.E.",UPPER(TRIM(E31))="UNITED ARAB EMIRATES"),"United Arab Emirates",IF(OR(UPPER(TRIM(E31))="SG",UPPER(TRIM(E31))="SINGAPORE"),"Singapore",TRIM(E31))))))))) -> United Kingdom | G31: Headphones | H31: Electronics | I31: 5 | J31: 85 | K31: 44 | L31: 0.2 | M31: Credit Card | N31: =PROPER(TRIM(M31)) -> Credit Card | O31: Completed | P31: =PROPER(TRIM(O31)) -> Completed | Q31: =IF(TRIM(R31)="","Missing",IF(AND(ISNUMBER(SEARCH("@",R31)),ISNUMBER(SEARCH(".",R31,SEARCH("@",R31)+2))),"Valid","Invalid")) -> Valid | R31: benjamin.walker@example.com | S31: =I31*J31*(1-L31) -> 340 | T31: =I31*K31 -> 220 | U31: =S31-T31 -> 120 | V31: =IF(S31=0,0,U31/S31) -> 0.35294118
A32: ORD-10372 | B32: 45778 | C32: grace moore | D32: =PROPER(TRIM(C32)) -> Grace Moore | E32: Singapore | F32: =IF(OR(UPPER(TRIM(E32))="AUS",UPPER(TRIM(E32))="AUSTRALIA"),"Australia",IF(OR(UPPER(TRIM(E32))="CAN",UPPER(TRIM(E32))="CANADA"),"Canada",IF(OR(UPPER(TRIM(E32))="DE",UPPER(TRIM(E32))="GERMANY"),"Germany",IF(OR(UPPER(TRIM(E32))="IN",UPPER(TRIM(E32))="INDIA"),"India",IF(OR(UPPER(TRIM(E32))="US",UPPER(TRIM(E32))="USA",UPPER(TRIM(E32))="UNITED STATES"),"United States",IF(OR(UPPER(TRIM(E32))="UK",UPPER(TRIM(E32))="U.K.",UPPER(TRIM(E32))="UNITED KINGDOM"),"United Kingdom",IF(OR(UPPER(TRIM(E32))="UAE",UPPER(TRIM(E32))="U.A.E.",UPPER(TRIM(E32))="UNITED ARAB EMIRATES"),"United Arab Emirates",IF(OR(UPPER(TRIM(E32))="SG",UPPER(TRIM(E32))="SINGAPORE"),"Singapore",TRIM(E32))))))))) -> Singapore | G32: Desk Lamp | H32: Furniture | I32: 1 | J32: 36 | K32: 16 | L32: 0.1 | M32: paypal | N32: PayPal | O32: Completed | P32: =PROPER(TRIM(O32)) -> Completed | Q32: =IF(TRIM(R32)="","Missing",IF(AND(ISNUMBER(SEARCH("@",R32)),ISNUMBER(SEARCH(".",R32,SEARCH("@",R32)+2))),"Valid","Invalid")) -> Valid | R32: grace.moore@example.com | S32: =I32*J32*(1-L32) -> 32.4 | T32: =I32*K32 -> 16 | U32: =S32-T32 -> 16.4 | V32: =IF(S32=0,0,U32/S32) -> 0.50617284
A33: ORD-10306 | B33: 45811 | C33: Benjamin Walker | D33: =PROPER(TRIM(C33)) -> Benjamin Walker | E33: US | F33: =IF(OR(UPPER(TRIM(E33))="AUS",UPPER(TRIM(E33))="AUSTRALIA"),"Australia",IF(OR(UPPER(TRIM(E33))="CAN",UPPER(TRIM(E33))="CANADA"),"Canada",IF(OR(UPPER(TRIM(E33))="DE",UPPER(TRIM(E33))="GERMANY"),"Germany",IF(OR(UPPER(TRIM(E33))="IN",UPPER(TRIM(E33))="INDIA"),"India",IF(OR(UPPER(TRIM(E33))="US",UPPER(TRIM(E33))="USA",UPPER(TRIM(E33))="UNITED STATES"),"United States",IF(OR(UPPER(TRIM(E33))="UK",UPPER(TRIM(E33))="U.K.",UPPER(TRIM(E33))="UNITED KINGDOM"),"United Kingdom",IF(OR(UPPER(TRIM(E33))="UAE",UPPER(TRIM(E33))="U.A.E.",UPPER(TRIM(E33))="UNITED ARAB EMIRATES"),"United Arab Emirates",IF(OR(UPPER(TRIM(E33))="SG",UPPER(TRIM(E33))="SINGAPORE"),"Singapore",TRIM(E33))))))))) -> United States | G33: Office Chair | H33: Furniture | I33: 4 | J33: 210 | K33: 125 | L33: 0.05 | M33: paypal | N33: PayPal | O33: Completed | P33: =PROPER(TRIM(O33)) -> Completed | Q33: =IF(TRIM(R33)="","Missing",IF(AND(ISNUMBER(SEARCH("@",R33)),ISNUMBER(SEARCH(".",R33,SEARCH("@",R33)+2))),"Valid","Invalid")) -> Valid | R33: benjamin.walker@example.com | S33: =I33*J33*(1-L33) -> 798 | T33: =I33*K33 -> 500 | U33: =S33-T33 -> 298 | V33: =IF(S33=0,0,U33/S33) -> 0.37343358
A34: ORD-10444 | B34: 45747 | C34: Ella Martin | D34: =PROPER(TRIM(C34)) -> Ella Martin | E34: Australia | F34: =IF(OR(UPPER(TRIM(E34))="AUS",UPPER(TRIM(E34))="AUSTRALIA"),"Australia",IF(OR(UPPER(TRIM(E34))="CAN",UPPER(TRIM(E34))="CANADA"),"Canada",IF(OR(UPPER(TRIM(E34))="DE",UPPER(TRIM(E34))="GERMANY"),"Germany",IF(OR(UPPER(TRIM(E34))="IN",UPPER(TRIM(E34))="INDIA"),"India",IF(OR(UPPER(TRIM(E34))="US",UPPER(TRIM(E34))="USA",UPPER(TRIM(E34))="UNITED STATES"),"United States",IF(OR(UPPER(TRIM(E34))="UK",UPPER(TRIM(E34))="U.K.",UPPER(TRIM(E34))="UNITED KINGDOM"),"United Kingdom",IF(OR(UPPER(TRIM(E34))="UAE",UPPER(TRIM(E34))="U.A.E.",UPPER(TRIM(E34))="UNITED ARAB EMIRATES"),"United Arab Emirates",IF(OR(UPPER(TRIM(E34))="SG",UPPER(TRIM(E34))="SINGAPORE"),"Singapore",TRIM(E34))))))))) -> Australia | G34: Monitor 27-inch | H34: Electronics | I34: 3 | J34: 245 | K34: 150 | L34: 0.1 | M34: Bank Transfer | N34: =PROPER(TRIM(M34)) -> Bank Transfer | O34: Cancelled | P34: =PROPER(TRIM(O34)) -> Cancelled | Q34: =IF(TRIM(R34)="","Missing",IF(AND(ISNUMBER(SEARCH("@",R34)),ISNUMBER(SEARCH(".",R34,SEARCH("@",R34)+2))),"Valid","Invalid")) -> Valid | R34: ella.martin@example.com | S34: =I34*J34*(1-L34) -> 661.5 | T34: =I34*K34 -> 450 | U34: =S34-T34 -> 211.5 | V34: =IF(S34=0,0,U34/S34) -> 0.31972789
A35: ORD-10201 | B35: 45967 | C35: Alex Morgan | D35: =PROPER(TRIM(C35)) -> Alex Morgan | E35: US | F35: =IF(OR(UPPER(TRIM(E35))="AUS",UPPER(TRIM(E35))="AUSTRALIA"),"Australia",IF(OR(UPPER(TRIM(E35))="CAN",UPPER(TRIM(E35))="CANADA"),"Canada",IF(OR(UPPER(TRIM(E35))="DE",UPPER(TRIM(E35))="GERMANY"),"Germany",IF(OR(UPPER(TRIM(E35))="IN",UPPER(TRIM(E35))="INDIA"),"India",IF(OR(UPPER(TRIM(E35))="US",UPPER(TRIM(E35))="USA",UPPER(TRIM(E35))="UNITED STATES"),"United States",IF(OR(UPPER(TRIM(E35))="UK",UPPER(TRIM(E35))="U.K.",UPPER(TRIM(E35))="UNITED KINGDOM"),"United Kingdom",IF(OR(UPPER(TRIM(E35))="UAE",UPPER(TRIM(E35))="U.A.E.",UPPER(TRIM(E35))="UNITED ARAB EMIRATES"),"United Arab Emirates",IF(OR(UPPER(TRIM(E35))="SG",UPPER(TRIM(E35))="SINGAPORE"),"Singapore",TRIM(E35))))))))) -> United States | G35: Headphones | H35: Electronics | I35: 4 | J35: 85 | K35: 44 | L35: 0.05 | M35: credit card | N35: =PROPER(TRIM(M35)) -> Credit Card | O35: Pending | P35: =PROPER(TRIM(O35)) -> Pending | Q35: =IF(TRIM(R35)="","Missing",IF(AND(ISNUMBER(SEARCH("@",R35)),ISNUMBER(SEARCH(".",R35,SEARCH("@",R35)+2))),"Valid","Invalid")) -> Valid | R35: alex.morgan@example.com | S35: =I35*J35*(1-L35) -> 323 | T35: =I35*K35 -> 176 | U35: =S35-T35 -> 147 | V35: =IF(S35=0,0,U35/S35) -> 0.45510836
A36: ORD-10223 | B36: 45938 | C36: Ethan Anderson | D36: =PROPER(TRIM(C36)) -> Ethan Anderson | E36: India | F36: =IF(OR(UPPER(TRIM(E36))="AUS",UPPER(TRIM(E36))="AUSTRALIA"),"Australia",IF(OR(UPPER(TRIM(E36))="CAN",UPPER(TRIM(E36))="CANADA"),"Canada",IF(OR(UPPER(TRIM(E36))="DE",UPPER(TRIM(E36))="GERMANY"),"Germany",IF(OR(UPPER(TRIM(E36))="IN",UPPER(TRIM(E36))="INDIA"),"India",IF(OR(UPPER(TRIM(E36))="US",UPPER(TRIM(E36))="USA",UPPER(TRIM(E36))="UNITED STATES"),"United States",IF(OR(UPPER(TRIM(E36))="UK",UPPER(TRIM(E36))="U.K.",UPPER(TRIM(E36))="UNITED KINGDOM"),"United Kingdom",IF(OR(UPPER(TRIM(E36))="UAE",UPPER(TRIM(E36))="U.A.E.",UPPER(TRIM(E36))="UNITED ARAB EMIRATES"),"United Arab Emirates",IF(OR(UPPER(TRIM(E36))="SG",UPPER(TRIM(E36))="SINGAPORE"),"Singapore",TRIM(E36))))))))) -> India | G36: Wireless Mouse | H36: Accessories | I36: 3 | J36: 18 | K36: 7 | L36: 0 | M36: PayPal | N36: PayPal | O36: Cancelled | P36: =PROPER(TRIM(O36)) -> Cancelled | Q36: =IF(TRIM(R36)="","Missing",IF(AND(ISNUMBER(SEARCH("@",R36)),ISNUMBER(SEARCH(".",R36,SEARCH("@",R36)+2))),"Valid","Invalid")) -> Valid | R36: ethan.anderson@example.com | S36: =I36*J36*(1-L36) -> 54 | T36: =I36*K36 -> 21 | U36: =S36-T36 -> 33 | V36: =IF(S36=0,0,U36/S36) -> 0.61111111
A37: ORD-10379 | B37: 45772 | C37: Mia White | D37: =PROPER(TRIM(C37)) -> Mia White | E37: india | F37: =IF(OR(UPPER(TRIM(E37))="AUS",UPPER(TRIM(E37))="AUSTRALIA"),"Australia",IF(OR(UPPER(TRIM(E37))="CAN",UPPER(TRIM(E37))="CANADA"),"Canada",IF(OR(UPPER(TRIM(E37))="DE",UPPER(TRIM(E37))="GERMANY"),"Germany",IF(OR(UPPER(TRIM(E37))="IN",UPPER(TRIM(E37))="INDIA"),"India",IF(OR(UPPER(TRIM(E37))="US",UPPER(TRIM(E37))="USA",UPPER(TRIM(E37))="UNITED STATES"),"United States",IF(OR(UPPER(TRIM(E37))="UK",UPPER(TRIM(E37))="U.K.",UPPER(TRIM(E37))="UNITED KINGDOM"),"United Kingdom",IF(OR(UPPER(TRIM(E37))="UAE",UPPER(TRIM(E37))="U.A.E.",UPPER(TRIM(E37))="UNITED ARAB EMIRATES"),"United Arab Emirates",IF(OR(UPPER(TRIM(E37))="SG",UPPER(TRIM(E37))="SINGAPORE"),"Singapore",TRIM(E37))))))))) -> India | G37: Office Chair | H37: Furniture | I37: 2 | J37: 210 | K37: 125 | L37: 0.15 | M37: PayPal | N37: PayPal | O37: Shipped | P37: =PROPER(TRIM(O37)) -> Shipped | Q37: =IF(TRIM(R37)="","Missing",IF(AND(ISNUMBER(SEARCH("@",R37)),ISNUMBER(SEARCH(".",R37,SEARCH("@",R37)+2))),"Valid","Invalid")) -> Valid | R37: mia.white@example.com | S37: =I37*J37*(1-L37) -> 357 | T37: =I37*K37 -> 250 | U37: =S37-T37 -> 107 | V37: =IF(S37=0,0,U37/S37) -> 0.29971989
A38: ORD-10141 | B38: 45983 | C38: James Thompson | D38: =PROPER(TRIM(C38)) -> James Thompson | E38: Singapore | F38: =IF(OR(UPPER(TRIM(E38))="AUS",UPPER(TRIM(E38))="AUSTRALIA"),"Australia",IF(OR(UPPER(TRIM(E38))="CAN",UPPER(TRIM(E38))="CANADA"),"Canada",IF(OR(UPPER(TRIM(E38))="DE",UPPER(TRIM(E38))="GERMANY"),"Germany",IF(OR(UPPER(TRIM(E38))="IN",UPPER(TRIM(E38))="INDIA"),"India",IF(OR(UPPER(TRIM(E38))="US",UPPER(TRIM(E38))="USA",UPPER(TRIM(E38))="UNITED STATES"),"United States",IF(OR(UPPER(TRIM(E38))="UK",UPPER(TRIM(E38))="U.K.",UPPER(TRIM(E38))="UNITED KINGDOM"),"United Kingdom",IF(OR(UPPER(TRIM(E38))="UAE",UPPER(TRIM(E38))="U.A.E.",UPPER(TRIM(E38))="UNITED ARAB EMIRATES"),"United Arab Emirates",IF(OR(UPPER(TRIM(E38))="SG",UPPER(TRIM(E38))="SINGAPORE"),"Singapore",TRIM(E38))))))))) -> Singapore | G38: Monitor 27-inch | H38: Electronics | I38: 2 | J38: 245 | K38: 150 | L38: 0.1 | M38: paypal | N38: PayPal | O38: Completed | P38: =PROPER(TRIM(O38)) -> Completed | Q38: =IF(TRIM(R38)="","Missing",IF(AND(ISNUMBER(SEARCH("@",R38)),ISNUMBER(SEARCH(".",R38,SEARCH("@",R38)+2))),"Valid","Invalid")) -> Invalid | R38: james.thompson@example | S38: =I38*J38*(1-L38) -> 441 | T38: =I38*K38 -> 300 | U38: =S38-T38 -> 141 | V38: =IF(S38=0,0,U38/S38) -> 0.31972789
A39: ORD-10149 | B39: 45838 | C39: Ethan Anderson | D39: =PROPER(TRIM(C39)) -> Ethan Anderson | E39: IN | F39: =IF(OR(UPPER(TRIM(E39))="AUS",UPPER(TRIM(E39))="AUSTRALIA"),"Australia",IF(OR(UPPER(TRIM(E39))="CAN",UPPER(TRIM(E39))="CANADA"),"Canada",IF(OR(UPPER(TRIM(E39))="DE",UPPER(TRIM(E39))="GERMANY"),"Germany",IF(OR(UPPER(TRIM(E39))="IN",UPPER(TRIM(E39))="INDIA"),"India",IF(OR(UPPER(TRIM(E39))="US",UPPER(TRIM(E39))="USA",UPPER(TRIM(E39))="UNITED STATES"),"United States",IF(OR(UPPER(TRIM(E39))="UK",UPPER(TRIM(E39))="U.K.",UPPER(TRIM(E39))="UNITED KINGDOM"),"United Kingdom",IF(OR(UPPER(TRIM(E39))="UAE",UPPER(TRIM(E39))="U.A.E.",UPPER(TRIM(E39))="UNITED ARAB EMIRATES"),"United Arab Emirates",IF(OR(UPPER(TRIM(E39))="SG",UPPER(TRIM(E39))="SINGAPORE"),"Singapore",TRIM(E39))))))))) -> India | G39: Webcam | H39: Electronics | I39: 3 | J39: 59 | K39: 30 | L39: 0.15 | M39: PayPal | N39: PayPal | O39: Shipped | P39: =PROPER(TRIM(O39)) -> Shipped | Q39: =IF(TRIM(R39)="","Missing",IF(AND(ISNUMBER(SEARCH("@",R39)),ISNUMBER(SEARCH(".",R39,SEARCH("@",R39)+2))),"Valid","Invalid")) -> Valid | R39: ethan.anderson@example.com | S39: =I39*J39*(1-L39) -> 150.45 | T39: =I39*K39 -> 90 | U39: =S39-T39 -> 60.45 | V39: =IF(S39=0,0,U39/S39) -> 0.40179462
A40: ORD-10546 | B40: 45773 | C40: Benjamin Walker | D40: =PROPER(TRIM(C40)) -> Benjamin Walker | E40: United Arab Emirates | F40: =IF(OR(UPPER(TRIM(E40))="AUS",UPPER(TRIM(E40))="AUSTRALIA"),"Australia",IF(OR(UPPER(TRIM(E40))="CAN",UPPER(TRIM(E40))="CANADA"),"Canada",IF(OR(UPPER(TRIM(E40))="DE",UPPER(TRIM(E40))="GERMANY"),"Germany",IF(OR(UPPER(TRIM(E40))="IN",UPPER(TRIM(E40))="INDIA"),"India",IF(OR(UPPER(TRIM(E40))="US",UPPER(TRIM(E40))="USA",UPPER(TRIM(E40))="UNITED STATES"),"United States",IF(OR(UPPER(TRIM(E40))="UK",UPPER(TRIM(E40))="U.K.",UPPER(TRIM(E40))="UNITED KINGDOM"),"United Kingdom",IF(OR(UPPER(TRIM(E40))="UAE",UPPER(TRIM(E40))="U.A.E.",UPPER(TRIM(E40))="UNITED ARAB EMIRATES"),"United Arab Emirates",IF(OR(UPPER(TRIM(E40))="SG",UPPER(TRIM(E40))="SINGAPORE"),"Singapore",TRIM(E40))))))))) -> United Arab Emirates | G40: Laptop Stand | H40: Accessories | I40: 5 | J40: 38 | K40: 17 | L40: 0.15 | M40: PayPal | N40: PayPal | O40: Completed | P40: =PROPER(TRIM(O40)) -> Completed | Q40: =IF(TRIM(R40)="","Missing",IF(AND(ISNUMBER(SEARCH("@",R40)),ISNUMBER(SEARCH(".",R40,SEARCH("@",R40)+2))),"Valid","Invalid")) -> Valid | R40: benjamin.walker@example.com | S40: =I40*J40*(1-L40) -> 161.5 | T40: =I40*K40 -> 85 | U40: =S40-T40 -> 76.5 | V40: =IF(S40=0,0,U40/S40) -> 0.47368421
...

Sheet KPI_Summary
A1: KPI | B1: Value
A2: Total Revenue | B2: =SUM(Clean_Data!S2:S551) -> 147019.1
A3: Total Cost | B3: =SUM(Clean_Data!T2:T551) -> 88021
A4: Gross Profit | B4: =SUM(Clean_Data!U2:U551) -> 58998.1
A5: Overall Profit Margin | B5: =IF(B2=0,0,B4/B2) -> 0.40129548
A6: Total Orders | B6: =COUNTA(Clean_Data!A2:A551) -> 550
A7: Average Order Value | B7: =IF(B6=0,0,B2/B6) -> 267.30745

Sheet Raw_Data
A1: Order_ID | B1: Order_Date | C1: Customer_Name | D1: Country | E1: Product | F1: Category | G1: Quantity | H1: Unit_Price_USD | I1: Unit_Cost_USD | J1: Discount | K1: Payment_Method | L1: Order_Status | M1: Customer_Email
A2: ORD-10087 | B2: 45735 | C2: Liam Miller | D2: UAE | E2: Desk Lamp | F2: Furniture | G2: 3 | H2: 36 | I2: 16 | J2: 0 | K2: paypal | L2: Completed | M2: liam.miller@example.com
A3: ORD-10007 | B3: 45894 | C3: Ava Thomas | D3: UAE | E3: Laptop Stand | F3: Accessories | G3: 4 | H3: 38 | I3: 17 | J3: 0 | K3: credit card | L3: Completed | M3: ava.thomas@example.com
A4: ORD-10143 | B4: 45777 | C4: alex morgan | D4: australia | E4: Wireless Mouse | F4: Accessories | G4: 1 | H4: 18 | I4: 7 | J4: 0.05 | K4: PayPal | L4: Completed | M4: alex.morgan@example.com
A5: ORD-10127 | B5: 45834 | C5: Liam Miller | D5: UK | E5: SSD 1TB | F5: Storage | G5: 1 | H5: 92 | I5: 53 | J5: 0 | K5: credit card | L5: Completed | M5: liam.miller@example.com
A6: ORD-10470 | B6: 46000 | C6: Lily Hall | D6: AUS | E6: SSD 1TB | F6: Storage | G6: 1 | H6: 92 | I6: 53 | J6: 0.05 | K6: Bank Transfer | L6: Pending | M6: lily.hall@example.com
A7: ORD-10279 | B7: 45764 | C7: Sophia Taylor | D7: germany | E7: External HDD 2TB | F7: Storage | G7: 5 | H7: 78 | I7: 45 | J7: 0.1 | K7: Debit Card | L7: Completed | M7: sophia.taylor@example.com
A8: ORD-10463 | B8: 45900 | C8: Daniel Harris | D8: USA | E8: Desk Lamp | F8: Furniture | G8: 2 | H8: 36 | I8: 16 | J8: 0.15 | K8: Bank Transfer | L8: Completed | M8: daniel.harris@example
A9: ORD-10041 | B9: 45753 | C9: Mia White | D9: germany | E9: Headphones | F9: Electronics | G9: 4 | H9: 85 | I9: 44 | J9: 0 | K9: credit card | L9: Completed | M9: mia.white@example.com
A10: ORD-10207 | B10: 45743 | C10: Grace Moore | D10: SG | E10: USB-C Hub | F10: Accessories | G10: 3 | H10: 42 | I10: 21 | J10: 0.05 | K10: paypal | L10: Cancelled | M10: grace.moore@example.com
A11: ORD-10011 | B11: 45914 | C11: Henry Clark | D11: CAN | E11: Office Chair | F11: Furniture | G11: 1 | H11: 210 | I11: 125 | J11: 0.05 | K11: PayPal | L11: Cancelled | M11: henry.clark@example.com
A12: ORD-10049 | B12: 45801 | C12: Olivia Davis | D12: DE | E12: Webcam | F12: Electronics | G12: 3 | H12: 59 | I12: 30 | J12: 0.05 | K12: credit card | L12: Completed | M12: olivia.davis@example.com
A13: ORD-10215 | B13: 45918 | C13: Daniel Harris | D13: SG | E13: USB-C Hub | F13: Accessories | G13: 3 | H13: 42 | I13: 21 | J13: 0 | K13: paypal | L13: Pending | M13: daniel.harris@example.com
... A19: ORD-10072 | B19: 45704 | C19: Lucas Jackson | D19: USA | E19: Mechanical Keyboard | F19: Accessories | G19: 2 | H19: 65 | I19: 31 | J19: 0.1 | K19: paypal | L19: Completed | M19: lucas.jackson@example.com
A20: ORD-10033 | B20: 45979 | C20: Henry Clark | D20: US | E20: Laptop Stand | F20: Accessories | G20: 4 | H20: 38 | I20: 17 | J20: 0.15 | K20: Bank Transfer | L20: Pending
A21: ORD-10264 | B21: 45815 | C21: Chloe Lewis | D21: DE | E21: SSD 1TB | F21: Storage | G21: 1 | H21: 92 | I21: 53 | J21: 0.2 | K21: Bank Transfer | L21: Shipped | M21: chloe.lewis@example.com
A22: ORD-10210 | B22: 45889 | C22: Chloe Lewis | D22: United Kingdom | E22: Webcam | F22: Electronics | G22: 4 | H22: 59 | I22: 30 | J22: 0.15 | K22: Credit Card | L22: Completed
A23: ORD-10274 | B23: 45831 | C23: Ava Thomas | D23: Singapore | E23: External HDD 2TB | F23: Storage | G23: 4 | H23: 78 | I23: 45 | J23: 0.1 | L23: Pending | M23: ava.thomas@example.com
A24: ORD-10004 | B24: 45792 | C24: Noah Brown | D24: Australia | E24: USB-C Hub | F24: Accessories | G24: 4 | H24: 42 | I24: 21 | J24: 0.05 | K24: Credit Card | L24: Cancelled | M24: noah.brown@example.com
A25: ORD-10200 | B25: 45933 | C25: Noah Brown | D25: Canada | E25: Webcam | F25: Electronics | G25: 2 | H25: 59 | I25: 30 | J25: 0 | K25: PayPal | L25: Completed | M25: noah.brown@example.com
A26: ORD-10191 | B26: 45684 | C26: Emma Wilson | D26: US | E26: Headphones | F26: Electronics | G26: 4 | H26: 85 | I26: 44 | J26: 0.05 | K26: paypal | L26: Cancelled | M26: emma.wilson@example.com
A27: ORD-10266 | B27: 45733 | C27: Henry Clark | D27: India | E27: Mechanical Keyboard | F27: Accessories | G27: 1 | H27: 65 | I27: 31 | J27: 0 | K27: Credit Card | L27: Pending | M27: henry.clark@example.com
A28: ORD-10280 | B28: 45852 | C28: Ella Martin | D28: germany | E28: SSD 1TB | F28: Storage | G28: 2 | H28: 92 | I28: 53 | J28: 0.05 | K28: Debit Card | L28: Shipped | M28: ella.martin@example.com
A29: ORD-10209 | B29: 45845 | C29: Olivia Davis | D29: U.K. | E29: Webcam | F29: Electronics | G29: 5 | H29: 59 | I29: 30 | J29: 0.2 | K29: credit card | L29: Completed | M29: olivia.davis@example.com
A30: ORD-10028 | B30: 45706 | C30: olivia davis | D30: Germany | E30: Wireless Mouse | F30: Accessories | G30: 4 | H30: 18 | I30: 7 | J30: 0.1 | K30: Debit Card | L30: Completed | M30: olivia.davis@example.com
